<?xml version="1.0" ?>
<robot name="ur3_cleaned">

  <!-- base link -->
  <link name="base_link"/>

  <!-- shoulder joint -->
  <joint name="shoulder_pan_joint" type="revolute">
    <parent link="base_link"/>
    <child link="shoulder_link"/>
    <origin xyz="0 0 0.1519" rpy="0 0 0"/>
    <axis xyz="0 0 1"/>
  </joint>
  <link name="shoulder_link"/>

  <!-- shoulder lift joint -->
  <joint name="shoulder_lift_joint" type="revolute">
    <parent link="shoulder_link"/>
    <child link="upper_arm_link"/>
    <origin xyz="0 0.1198 0" rpy="0 1.5708 0"/>
    <axis xyz="0 1 0"/>
  </joint>
  <link name="upper_arm_link"/>

  <!-- elbow joint -->
  <joint name="elbow_joint" type="revolute">
    <parent link="upper_arm_link"/>
    <child link="forearm_link"/>
    <origin xyz="0 -0.0925 0.24365" rpy="0 0 0"/>
    <axis xyz="0 1 0"/>
  </joint>
  <link name="forearm_link"/>

  <!-- wrist 1 joint -->
  <joint name="wrist_1_joint" type="revolute">
    <parent link="forearm_link"/>
    <child link="wrist_1_link"/>
    <origin xyz="0 0 0.21325" rpy="0 1.5708 0"/>
    <axis xyz="0 1 0"/>
  </joint>
  <link name="wrist_1_link"/>

  <!-- Wrist 2 joint -->
  <joint name="wrist_2_joint" type="revolute">
    <parent link="wrist_1_link"/>
    <child link="wrist_2_link"/>
    <origin xyz="0 0.08505 0" rpy="0 0 0"/>
    <axis xyz="0 0 1"/>
  </joint>
  <link name="wrist_2_link"/>

  <!-- Wrist 3 joint -->
  <joint name="wrist_3_joint" type="revolute">
    <parent link="wrist_2_link"/>
    <child link="wrist_3_link"/>
    <origin xyz="0 0 0.08535" rpy="0 0 0"/>
    <axis xyz="0 1 0"/>
  </joint>
  <link name="wrist_3_link"/>

  <!-- End-effector -->
  <joint name="ee_fixed_joint" type="fixed">
    <parent link="wrist_3_link"/>
    <child link="ee_link"/>
    <origin xyz="0 0.0819 0" rpy="0 0 1.5708"/>
  </joint>
  <link name="ee_link"/>

</robot>
